<?xml version="1.0" ?>
<robot name = "robot_arm">

<!--base link-->
<link name = "base_link" />

<!-- link 0 -->
<link name = "link0">
    <visual>
        <geometry>
        <mesh filename="package://ros_project/meshes/Part1.stl" scale="0.003 0.003 0.003"/>
 
        <cylinder length="0.1" radius="0.1"/>
        </geometry>
        <origin xyz="-0.125 -0.125 0" rpy="0 0 0"/>
    </visual>

    
    <inertial>
        <origin xyz="0 0 0" rpy="0 0 0"/>
        <mass value="1"/>
        <inertia ixx="0.001" ixy="0" ixz="0" iyy="0.001" iyz="0" izz="0"/>
    </inertial>
</link>



<!--joint0-->
<joint name="joint0" type="fixed">
    <parent link="base_link"/>
    <child link="link0"/>
   
    <origin xyz="0 0 0" rpy="0 0 0"/>
    <axis xyz="0 0 0"/>
    <limit lower="0" upper="180" effort="200" velocity="1"/>
</joint>




<!-- link 1 -->
<link name = "link1">
    <visual>
        <geometry>
            <mesh filename="package://ros_project/meshes/Part2.stl"  scale="0.003 0.003 0.003"/>
        </geometry>
        <origin xyz="-0.12 -0.115 0" rpy="0 0 0"/>
    </visual>

     

    <visual>
        <geometry>
            <mesh filename="package://ros_project/meshes/Part3.stl" scale="0.003 0.003 0.003"/>
        </geometry>
        <origin xyz="-0.09 -0.09 0.36" rpy="0 0 0"/>
    </visual>

     

    <inertial>
        <origin xyz="0 0 0" rpy="0 0 0"/>
        <mass value="1"/>
        <inertia ixx="0.01" ixy="0" ixz="0" iyy="0.01" iyz="0" izz="0.01"/>
    </inertial>
</link>



<!--joint2-->
<joint name="joint2" type="revolute">
    <parent link="link0"/>
    <child link="link1"/>
    <origin xyz="0 0 0.15" rpy="0 0 0"/>
    <axis xyz="0 0 1"/>
    <limit lower="-1.5" upper="1.5" effort="100" velocity="1"/>
</joint>




<!-- link 2 -->
<link name = "link2">
    <visual>
        <geometry>
            <mesh filename="package://ros_project/meshes/Part4.stl" scale="0.003 0.003 0.003"/>
        </geometry>
        <origin xyz="-0.1 -0.09 0.02" rpy="0 0 0"/>
    </visual>

    

    <inertial>
        <origin xyz="0 0 0" rpy="0 0 0"/>
        <mass value="1"/>
        <inertia ixx="0.001" ixy="0" ixz="0" iyy="0.001" iyz="0" izz="0"/>
    </inertial>
</link>


<!-- Joint 1 -->
    <joint name="joint1" type="revolute">
        <parent link="link1"/>
        <child link="link2"/>
        <origin xyz="0.45 0 0.4" rpy="0 0 -1.5"/>
        <axis xyz="0 0 1"/>
        <limit lower="-1.5" upper="1.5" effort="200" velocity="2.0"/>
    </joint>



</robot>